

============================== 2023-04-11 13:31:24.097079 | 11f704b8-1726-4d70-94a4-3a495d83ee43 ==============================
[0m13:31:24.097079 [info ] [MainThread]: Running with dbt=1.4.5
[0m13:31:24.097821 [debug] [MainThread]: running dbt with arguments {'write_json': True, 'use_colors': True, 'printer_width': 80, 'version_check': True, 'partial_parse': True, 'static_parser': True, 'profiles_dir': '/Users/thyer.myren/.dbt', 'send_anonymous_usage_stats': True, 'quiet': False, 'no_print': False, 'cache_selected_only': False, 'project_name': 'dbt_1', 'skip_profile_setup': False, 'which': 'init', 'indirect_selection': 'eager'}
[0m13:31:24.097935 [debug] [MainThread]: Tracking: tracking
[0m13:31:24.113374 [debug] [MainThread]: Sending event: {'category': 'dbt', 'action': 'invocation', 'label': 'start', 'context': [<snowplow_tracker.self_describing_json.SelfDescribingJson object at 0x104c8a680>, <snowplow_tracker.self_describing_json.SelfDescribingJson object at 0x104c8ab00>, <snowplow_tracker.self_describing_json.SelfDescribingJson object at 0x104c8b520>]}
[0m13:31:24.115069 [debug] [MainThread]: Starter project path: /Library/Frameworks/Python.framework/Versions/3.10/lib/python3.10/site-packages/dbt/include/starter_project
[0m13:31:26.506020 [debug] [MainThread]: Sending event: {'category': 'dbt', 'action': 'invocation', 'label': 'end', 'context': [<snowplow_tracker.self_describing_json.SelfDescribingJson object at 0x104c45f30>, <snowplow_tracker.self_describing_json.SelfDescribingJson object at 0x104c46e00>, <snowplow_tracker.self_describing_json.SelfDescribingJson object at 0x104c46350>]}
[0m13:31:26.506266 [debug] [MainThread]: Flushing usage events
[0m13:31:26.908117 [error] [MainThread]: Encountered an error:
cannot import name 'FailedToConnectException' from 'dbt.exceptions' (/Library/Frameworks/Python.framework/Versions/3.10/lib/python3.10/site-packages/dbt/exceptions.py)
[0m13:31:26.913035 [error] [MainThread]: Traceback (most recent call last):
  File "/Library/Frameworks/Python.framework/Versions/3.10/lib/python3.10/site-packages/dbt/main.py", line 136, in main
    results, succeeded = handle_and_check(args)
  File "/Library/Frameworks/Python.framework/Versions/3.10/lib/python3.10/site-packages/dbt/main.py", line 206, in handle_and_check
    task, res = run_from_args(parsed)
  File "/Library/Frameworks/Python.framework/Versions/3.10/lib/python3.10/site-packages/dbt/main.py", line 253, in run_from_args
    results = task.run()
  File "/Library/Frameworks/Python.framework/Versions/3.10/lib/python3.10/site-packages/dbt/task/init.py", line 305, in run
    self.create_profile_from_target(adapter, profile_name=project_name)
  File "/Library/Frameworks/Python.framework/Versions/3.10/lib/python3.10/site-packages/dbt/task/init.py", line 173, in create_profile_from_target
    load_plugin(adapter)
  File "/Library/Frameworks/Python.framework/Versions/3.10/lib/python3.10/site-packages/dbt/adapters/factory.py", line 202, in load_plugin
    return FACTORY.load_plugin(name)
  File "/Library/Frameworks/Python.framework/Versions/3.10/lib/python3.10/site-packages/dbt/adapters/factory.py", line 57, in load_plugin
    mod: Any = import_module("." + name, "dbt.adapters")
  File "/Library/Frameworks/Python.framework/Versions/3.10/lib/python3.10/importlib/__init__.py", line 126, in import_module
    return _bootstrap._gcd_import(name[level:], package, level)
  File "<frozen importlib._bootstrap>", line 1050, in _gcd_import
  File "<frozen importlib._bootstrap>", line 1027, in _find_and_load
  File "<frozen importlib._bootstrap>", line 1006, in _find_and_load_unlocked
  File "<frozen importlib._bootstrap>", line 688, in _load_unlocked
  File "<frozen importlib._bootstrap_external>", line 883, in exec_module
  File "<frozen importlib._bootstrap>", line 241, in _call_with_frames_removed
  File "/Library/Frameworks/Python.framework/Versions/3.10/lib/python3.10/site-packages/dbt/adapters/bigquery/__init__.py", line 1, in <module>
    from dbt.adapters.bigquery.connections import BigQueryConnectionManager  # noqa
  File "/Library/Frameworks/Python.framework/Versions/3.10/lib/python3.10/site-packages/dbt/adapters/bigquery/connections.py", line 26, in <module>
    from dbt.exceptions import (
ImportError: cannot import name 'FailedToConnectException' from 'dbt.exceptions' (/Library/Frameworks/Python.framework/Versions/3.10/lib/python3.10/site-packages/dbt/exceptions.py)

